Workbook

Sheet Summary
A1: BandLink — BOM & power summary
A2: CECS 490A Team 1 · scope: MVP + Stretch 1 + Stretch 2 · all values recalc from BOM / Power / Inputs tabs
A4: Section | B4: MVP $ | C4: S1 $ | D4: S2 $ | E4: Per unit/set $ | F4: Multiplier | G4: Section total $
A5: Dev bring-up (per set) | B5: =SUMIFS(BOM!$J$5:$J$44,BOM!$B$5:$B$44,$A5,BOM!$F$5:$F$44,"MVP") -> 187.5 | C5: =SUMIFS(BOM!$J$5:$J$44,BOM!$B$5:$B$44,$A5,BOM!$F$5:$F$44,"S1") -> 48 | D5: =SUMIFS(BOM!$J$5:$J$44,BOM!$B$5:$B$44,$A5,BOM!$F$5:$F$44,"S2") -> 35 | E5: =SUM(B5:D5) -> 270.5 | F5: =Inputs!B4 -> 2 | G5: =E5*F5 -> 541
A6: Custom PCB (per bracelet) | B6: =SUMIFS(BOM!$J$5:$J$44,BOM!$B$5:$B$44,$A6,BOM!$F$5:$F$44,"MVP") -> 107.75 | C6: =SUMIFS(BOM!$J$5:$J$44,BOM!$B$5:$B$44,$A6,BOM!$F$5:$F$44,"S1") -> 35.5 | D6: =SUMIFS(BOM!$J$5:$J$44,BOM!$B$5:$B$44,$A6,BOM!$F$5:$F$44,"S2") -> 23 | E6: =SUM(B6:D6) -> 166.25 | F6: =Inputs!B3 -> 3 | G6: =E6*F6 -> 498.75
A7: Team tools (one-time) | B7: =SUMIFS(BOM!$J$5:$J$44,BOM!$B$5:$B$44,$A7,BOM!$F$5:$F$44,"MVP") -> 111 | C7: =SUMIFS(BOM!$J$5:$J$44,BOM!$B$5:$B$44,$A7,BOM!$F$5:$F$44,"S1") -> 130 | D7: =SUMIFS(BOM!$J$5:$J$44,BOM!$B$5:$B$44,$A7,BOM!$F$5:$F$44,"S2") -> 0 | E7: =SUM(B7:D7) -> 241 | F7: 1 | G7: =E7*F7 -> 241
A8: Project total | G8: =SUM(G5:G7) -> 1280.75
A9: MVP-only spend (dev sets + MVP tools) | G9: =B5*F5+B7 -> 486
A10: Line items priced as estimates | G10: =COUNTIF(BOM!K5:K44,"Estimate")&" of "&COUNTA(BOM!K5:K44) -> 34 of 40
A12: Power (final build) | B12: Standby | C12: Typical | D12: Finding | E12: Blended day | G12: R-03 target
A13: Battery current (mA) | B13: =Power!H26 -> 16.615374 | C13: =Power!I26 -> 24.351925 | D13: =Power!J26 -> 59.998332 | E13: =Power!H30 -> 25.982428
A14: Runtime (h) | B14: =Power!H27 -> 25.578721 | C14: =Power!I27 -> 17.452419 | D14: =Power!J27 -> 7.0835302 | E14: =Power!H31 -> 16.357209 | G14: =Inputs!B10 -> 8
A15: Managed peak at battery (mA) / C-rate | B15: =Power!K37 -> 452.99294 | C15: =Power!K38 -> 0.90598588
A16: LoRa time on air per packet (s) / FCC dwell | B16: =Inputs!B25 -> 0.205824 | C16: =Inputs!B27 -> OK
A18: Design decisions baked into this BOM
A19: 1. BQ25120A dropped as the system regulator: its 300 mA buck is below the ~350 mA managed rail peak (530 mA worst case). TPS63802 buck-boost for 3.3 V, BQ25180 for charging.
A20: 2. SX1262 VBAT abs-max is below a full LiPo (4.2 V): radio sits on the 3.3 V rail, never on raw battery.
A21: 3. Biggest power levers, in order: GNSS duty (power-save / cyclic tracking), LoRa RX scheduling (GPS-synced TDMA, Inputs!B28), AMOLED on-time.
A22: 4. Firmware interlock: never run the NFC field during LoRa TX or UWB ranging - keeps the peak inside the cell's pulse rating.
A23: 5. UWB (S2) is distance-only; direction still comes from GPS bearing + BNO085 rotation-vector heading.
A24: 6. Multi-hop relay (S2) is firmware-only - no BOM cost, modeled as the relay TX multiplier on the Power tab.
A25: 7. Red 'Estimate' prices on the BOM tab need a distributor check before the order goes in.

Sheet Inputs
A1: Inputs & assumptions
A2: Blue = editable input. Yellow = key assumption worth measuring. Black = formula.
A3: Bracelets to build (custom PCB, 490B) | B3: 3 | C3: 2 for demo + 1 spare
A4: Dev-board sets (490A bring-up) | B4: 2 | C4: One set per bracelet for the 500 m MVP test
A5: Battery capacity (mAh) | B5: 500 | C5: Adafruit 1578, 500 mAh w/ PCM, 29x36x4.75 mm (was 370 mAh Jauch LP402535)
A6: Usable capacity fraction | B6: 0.85 | C6: Cutoff at 3.0 V, aging, cold; small LiPo cells rarely deliver rated mAh at load
A7: Battery nominal voltage (V) | B7: 3.7
A8: Main rail voltage (V) | B8: 3.3 | C8: All loads modeled at 3.3 V rail; 1.8 V loads sit behind an LDO from 3.3 V
A9: Buck-boost efficiency (typical load) | B9: 0.9 | C9: TPS63802-class at 10-100 mA
A10: R-03 runtime target (h) | B10: 8 | C10: From proposal R-03
A11: Battery min voltage (V) | B11: 3 | C11: Worst case for peak-current check
A12: Buck-boost efficiency at peak load | B12: 0.85
A13: Battery max pulse discharge (C) | B13: 2 | C13: Check the actual cell datasheet; many small cells are 1C cont / 2C pulse
A15: LoRa airtime (Semtech SX126x time-on-air formula)
A16: Spreading factor (SF) | B16: 9 | C16: SF9 is a reasonable start for 0.5-1 km wrist-to-wrist
A17: Bandwidth (Hz) | B17: 125000
A18: Coding rate index (1 = 4/5) | B18: 1
A19: Preamble symbols | B19: 8
A20: Payload bytes | B20: 24 | C20: id 2 + seq 2 + lat/lon 8 + alt 2 + time 4 + flags 2 + AES-CCM MIC 4
A21: CRC on (1/0) | B21: 1
A22: Implicit header (1/0) | B22: 0
A23: Low data rate optimize (auto) | B23: =IF(AND(B16>=11,B17<=125000),1,0) -> 0 | C23: Required for symbol time > 16 ms
A24: Symbol time (s) | B24: =2^B16/B17 -> 0.004096
A25: Time on air per packet (s) | B25: =(B19+4.25)*B24+(8+MAX(CEILING((8*B20-4*B16+28+16*B21-20*B22)/(4*(B16-2*B23)),1)*(B18+4),0))*B24 -> 0.205824
A26: FCC 15.247 dwell limit per channel (s) | B26: 0.4 | C26: Max 0.4 s per hop channel in a 20 s window (915 MHz FHSS)
A27: Dwell check | B27: =IF(B25<=B26,"OK","EXCEEDS - lower SF or payload") -> OK
A28: GPS-synced TDMA RX (1 = on, 0 = continuous RX) | B28: 0 | C28: Biggest single power lever: wake RX only in peers' PPS-aligned slots
A29: Paired peers in group | B29: 3
A30: RX guard per slot (s) | B30: 0.05 | C30: PPS jitter + SX1262 wake/calibration

Sheet BOM
A1: Bill of materials — scope locked through Stretch 2
A2: Prices are USD at qty 1-10. 'Sourced' = distributor listing found Oct 2026; 'Estimate' = verify before ordering. Tier: MVP / S1 / S2.
A4: # | B4: Section | C4: Subsystem | D4: Part | E4: MPN / SKU | F4: Tier | G4: Interface / bus | H4: Qty | I4: Unit $ | J4: Ext $ | K4: Price basis | L4: Notes
A5: 1 | B5: Dev bring-up (per set) | C5: MCU | D5: NUCLEO-U5A5ZJ-Q | E5: NUCLEO-U5A5ZJ-Q | F5: MVP | G5: SWD / USB | H5: 1 | I5: 30 | J5: =H5*I5 -> 30 | K5: Estimate | L5: Same U5 family + 2.5 MB SRAM, no GPU. MVP firmware runs here; port to U5A9 is pin/HAL-level.
A6: 2 | B6: Dev bring-up (per set) | C6: GNSS | D6: SparkFun GNSS Breakout MAX-M10S (Qwiic) | E6: GPS-18037 | F6: MVP | G6: UART (or I2C 0x42) + PPS | H6: 1 | I6: 45 | J6: =H6*I6 -> 45 | K6: Estimate | L6: Wire PPS to an EXTI/timer-capture pin now; TDMA depends on it.
A7: 3 | B7: Dev bring-up (per set) | C7: LoRa | D7: SX1262 915 MHz breakout + SMA whip | E7: e.g. Waveshare Core1262-HF | F7: MVP | G7: SPI + BUSY + DIO1 + NRESET | H7: 1 | I7: 20 | J7: =H7*I7 -> 20 | K7: Estimate | L7: Must poll BUSY before every SPI command.
A8: 4 | B8: Dev bring-up (per set) | C8: NFC | D8: MIKROE NFC 2 Click | E8: PN7150 | F8: MVP | G8: I2C + IRQ + VEN | H8: 1 | I8: 35 | J8: =H8*I8 -> 35 | K8: Sourced | L8: SparkFun listed $34.95 (retired there); buy from MIKROE.
A9: 5 | B9: Dev bring-up (per set) | C9: IMU (9-DOF fusion) | D9: Adafruit BNO085 9-DOF Orientation IMU Fusion Breakout (STEMMA QT) | E9: Adafruit 4754 | F9: MVP | G9: I2C 0x4A + INT + RST (SPI via PS0/PS1 jumpers) | H9: 1 | I9: 29.5 | J9: =H9*I9 -> 29.5 | K9: Sourced | L9: Team choice. Accel + gyro + mag + on-chip fusion: firmware reads a rotation-vector quaternion, so no host-side compass fusion or tilt compensation. Host I2C must support clock stretching.
A10: 6 | B10: Dev bring-up (per set) | C10: Display | D10: 1.28" round TFT 240x240 | E10: GC9A01 module | F10: MVP | G10: SPI | H10: 1 | I10: 10 | J10: =H10*I10 -> 10 | K10: Estimate | L10: Cheap MVP screen; LVGL port carries over to AMOLED.
A11: 7 | B11: Dev bring-up (per set) | C11: Haptic | D11: Coin ERM motor + MOSFET | E11: generic 10 mm ERM | F11: MVP | G11: GPIO / PWM | H11: 1 | I11: 3 | J11: =H11*I11 -> 3 | K11: Estimate
A12: 8 | B12: Dev bring-up (per set) | C12: Power | D12: USB power bank (field test) | E12: generic | F12: MVP | G12: USB | H12: 1 | I12: 15 | J12: =H12*I12 -> 15 | K12: Estimate | L12: Powers dev boards for the 500 m walk test.
A13: 9 | B13: Dev bring-up (per set) | C13: Display | D13: 1.43" AMOLED 466x466 module w/ touch | E13: Waveshare 1.43" AMOLED (CO5300) | F13: S1 | G13: QSPI (OCTOSPI) + I2C touch + TE | H13: 1 | I13: 25 | J13: =H13*I13 -> 25 | K13: Estimate | L13: Confirm driver IC (CO5300 vs SH8601) on the exact listing.
A14: 10 | B14: Dev bring-up (per set) | C14: Haptic | D14: DRV2605L breakout + 8 mm LRA | E14: Adafruit 2305 + G0832022D-class LRA | F14: S1 | G14: I2C + EN | H14: 1 | I14: 13 | J14: =H14*I14 -> 13 | K14: Estimate | L14: Run DRV2605L auto-calibration per LRA.
A15: 11 | B15: Dev bring-up (per set) | C15: Crown | D15: Bourns PEC06 encoder w/ switch | E15: PEC06 | F15: S1 | G15: 2x GPIO (TIM encoder mode) + 1 GPIO | H15: 1 | I15: 4 | J15: =H15*I15 -> 4 | K15: Estimate | L15: 6 pulses/rev; RC filter per Bourns app circuit.
A16: 12 | B16: Dev bring-up (per set) | C16: Power | D16: MAX17048 fuel gauge breakout | E16: Adafruit 5580 | F16: S1 | G16: I2C + ALRT | H16: 1 | I16: 6 | J16: =H16*I16 -> 6 | K16: Estimate
A17: 13 | B17: Dev bring-up (per set) | C17: UWB | D17: Qorvo DWM3000EVB (Arduino shield) | E17: DWM3000EVB | F17: S2 | G17: SPI + IRQ + WAKEUP + RSTn | H17: 1 | I17: 35 | J17: =H17*I17 -> 35 | K17: Estimate | L17: Distance only (single antenna) - no direction arrow.
A18: 14 | B18: Custom PCB (per bracelet) | C18: MCU | D18: STM32U5A9 4 MB flash, 2.5 MB SRAM, NeoChrom | E18: STM32U5A9VJT6Q (LQFP100) | F18: MVP | G18: - | H18: 1 | I18: 16 | J18: =H18*I18 -> 16 | K18: Estimate | L18: ST eStore $9.96 @10k. LQFP avoids BGA. Verify OCTOSPI pin availability for QSPI panel in LQFP100.
A19: 15 | B19: Custom PCB (per bracelet) | C19: MCU | D19: 32.768 kHz + HSE crystals | E19: - | F19: MVP | G19: - | H19: 1 | I19: 1.5 | J19: =H19*I19 -> 1.5 | K19: Estimate | L19: LSE needed for RTC/LPTIM in Stop 2.
A20: 16 | B20: Custom PCB (per bracelet) | C20: GNSS | D20: u-blox MAX-M10S | E20: MAX-M10S-00B | F20: MVP | G20: UART + PPS + RESET_N | H20: 1 | I20: 17 | J20: =H20*I20 -> 17 | K20: Estimate | L20: Integrated LNA + SAW: passive antenna OK.
A21: 17 | B21: Custom PCB (per bracelet) | C21: GNSS | D21: L1 chip antenna | E21: - | F21: MVP | G21: RF | H21: 1 | I21: 2 | J21: =H21*I21 -> 2 | K21: Estimate | L21: Needs ground plane + keepout; wrist detunes it.
A22: 18 | B22: Custom PCB (per bracelet) | C22: LoRa | D22: SX1262 module, 22 dBm, TCXO | E22: e.g. Ebyte E22-900M22S | F22: MVP | G22: SPI + BUSY + DIO1 + NRESET + RXEN/TXEN | H22: 1 | I22: 8 | J22: =H22*I22 -> 8 | K22: Estimate | L22: Module avoids chip-down RF layout. SX1262 VBAT max 3.7 V - feed from 3.3 V rail, never raw battery.
A23: 19 | B23: Custom PCB (per bracelet) | C23: LoRa | D23: 915 MHz antenna (FPC/chip) | E23: - | F23: MVP | G23: RF | H23: 1 | I23: 3 | J23: =H23*I23 -> 3 | K23: Estimate
A24: 20 | B24: Custom PCB (per bracelet) | C24: NFC | D24: NXP PN7150 NFC controller | E24: PN7150B0HN/C11002 | F24: MVP | G24: I2C + IRQ + VEN | H24: 1 | I24: 10 | J24: =H24*I24 -> 10 | K24: Sourced | L24: Farnell EUR 8.98 @5. PN7160 drops P2P - if you switch, pair via card emulation instead.
A25: 21 | B25: Custom PCB (per bracelet) | C25: NFC | D25: NFC antenna coil + matching network | E25: PCB trace or FPC | F25: MVP | G25: RF | H25: 1 | I25: 2 | J25: =H25*I25 -> 2 | K25: Estimate | L25: Metal/battery under coil kills coupling - use ferrite sheet.
A26: 22 | B26: Custom PCB (per bracelet) | C26: IMU (9-DOF fusion) | D26: CEVA BNO085 + 32.768 kHz crystal | E26: BNO085 | F26: MVP | G26: SPI (PS0/PS1 = 1/1) + H_INTN + NRST + PS0/WAKE | H26: 1 | I26: 18 | J26: =H26*I26 -> 18 | K26: Estimate | L26: VDD 2.4-3.6 V on the 3.3 V rail. Use SPI on the custom PCB to avoid BNO08x I2C quirks. BOOTN to a test pad for firmware updates. Keep away from the LRA magnet and battery.
A27: 23 | B27: Custom PCB (per bracelet) | C27: Power | D27: 3.3 V buck-boost | E27: TPS63802 | F27: MVP | G27: - | H27: 1 | I27: 2 | J27: =H27*I27 -> 2 | K27: Estimate | L27: Replaces BQ25120A buck (300 mA max is below the ~350 mA managed rail peak).
A28: 24 | B28: Custom PCB (per bracelet) | C28: Power | D28: 1.8 V LDO | E28: TLV75518P | F28: MVP | G28: - | H28: 1 | I28: 0.3 | J28: =H28*I28 -> 0.3 | K28: Estimate | L28: PN7150 pad supply (VDD(PAD) 1.65-1.95 V).
A29: 25 | B29: Custom PCB (per bracelet) | C29: Battery | D29: LiPo 500 mAh w/ PCM, 29x36x4.75 mm | E29: Adafruit 1578 | F29: MVP | G29: - | H29: 1 | I29: 7.95 | J29: =H29*I29 -> 7.95 | K29: Sourced | L29: Adafruit $7.95 qty1-9, 10.5 g, PCM cuts off at 3.0 V. Charge at <=1C (no thermistor in pack). Max discharge not published - confirm.
A30: 26 | B30: Custom PCB (per bracelet) | C30: PCB | D30: 4-layer PCB, ~40 mm round | E30: JLC-class | F30: MVP | G30: - | H30: 1 | I30: 6 | J30: =H30*I30 -> 6 | K30: Estimate | L30: Per-board share of a 5-pc order.
A31: 27 | B31: Custom PCB (per bracelet) | C31: Misc | D31: Passives, ESD/TVS, connectors | E31: - | F31: MVP | G31: - | H31: 1 | I31: 8 | J31: =H31*I31 -> 8 | K31: Estimate
A32: 28 | B32: Custom PCB (per bracelet) | C32: Mech | D32: Enclosure + strap | E32: 3D printed | F32: MVP | G32: - | H32: 1 | I32: 6 | J32: =H32*I32 -> 6 | K32: Estimate
A33: 29 | B33: Custom PCB (per bracelet) | C33: Display | D33: 1.43" AMOLED 466x466 panel w/ CTP | E33: CO5300 / SH8601 QSPI panel | F33: S1 | G33: QSPI + TE + RESET + I2C touch | H33: 1 | I33: 20 | J33: =H33*I33 -> 20 | K33: Estimate | L33: Check whether FPC needs external ELVDD/ELVSS supply - adds a PMIC if so.
A34: 30 | B34: Custom PCB (per bracelet) | C34: Haptic | D34: Haptic driver | E34: DRV2605LDGST | F34: S1 | G34: I2C + EN | H34: 1 | I34: 2.5 | J34: =H34*I34 -> 2.5 | K34: Estimate
A35: 31 | B35: Custom PCB (per bracelet) | C35: Haptic | D35: 8 mm coin LRA, 235 Hz | E35: 0832-class | F35: S1 | G35: - | H35: 1 | I35: 2 | J35: =H35*I35 -> 2 | K35: Estimate
A36: 32 | B36: Custom PCB (per bracelet) | C36: Crown | D36: Bourns PEC06 encoder | E36: PEC06 | F36: S1 | G36: GPIO | H36: 1 | I36: 2.5 | J36: =H36*I36 -> 2.5 | K36: Estimate
A37: 33 | B37: Custom PCB (per bracelet) | C37: Power | D37: Linear charger w/ power path | E37: BQ25180 | F37: S1 | G37: I2C + INT | H37: 1 | I37: 1.5 | J37: =H37*I37 -> 1.5 | K37: Estimate | L37: Power path keeps system alive while charging on the dock.
A38: 34 | B38: Custom PCB (per bracelet) | C38: Power | D38: Fuel gauge | E38: MAX17048G+T10 | F38: S1 | G38: I2C + ALRT | H38: 1 | I38: 3 | J38: =H38*I38 -> 3 | K38: Estimate | L38: 3 uA hibernate / 23 uA active.
A39: 35 | B39: Custom PCB (per bracelet) | C39: Power | D39: Magnetic pogo connector, 4-pin | E39: generic | F39: S1 | G39: VBUS, GND, UART TX/RX | H39: 1 | I39: 4 | J39: =H39*I39 -> 4 | K39: Estimate | L39: UART on pogo = bootloader + debug console on the dock.
A40: 36 | B40: Custom PCB (per bracelet) | C40: UWB | D40: Qorvo DWM3000 module | E40: DWM3000TR13 | F40: S2 | G40: SPI + IRQ + WAKEUP + RSTn | H40: 1 | I40: 23 | J40: =H40*I40 -> 23 | K40: Sourced | L40: DigiKey EUR 20.33. Use channel 5 (lower current than ch 9).
A41: 37 | B41: Team tools (one-time) | C41: UI dev | D41: STM32U5G9J-DK1 Discovery | E41: STM32U5G9J-DK1 | F41: S1 | G41: - | H41: 1 | I41: 90 | J41: =H41*I41 -> 90 | K41: Sourced | L41: Farnell EUR 86.14. NeoChrom + round display for LVGL bring-up. The U5A9J-DK is NRND.
...

Sheet Power
A1: Power budget — final build (MVP + S1 + S2 hardware)
A2: Currents at the 3.3 V rail. Avg = active x duty + sleep x (1 - duty). Edit blue duty cycles after measuring with the PPK2.
A4: Scenario parameters | E4: Standby tracking | F4: Typical event | G4: Active finding
A5: Own position TX interval (s) | E5: 10 | F5: 5 | G5: 2
A6: Relay TX multiplier (S2 multi-hop) | E6: 1 | F6: 1.5 | G6: 1.5
A7: Share of an 8 h event day | E7: 0.25 | F7: 0.65 | G7: 0.1 | H7: =SUM(E7:G7) -> 1 | I7: <- must be 100%
A8: LoRa TX duty | E8: =MIN(1,Inputs!$B$25/E5*E6) -> 0.0205824 | F8: =MIN(1,Inputs!$B$25/F5*F6) -> 0.0617472 | G8: =MIN(1,Inputs!$B$25/G5*G6) -> 0.154368
A9: LoRa RX duty | E9: =IF(Inputs!$B$28=1,MIN(1-E8,Inputs!$B$29*(Inputs!$B$25+Inputs!$B$30)/E5),1-E8) -> 0.9794176 | F9: =IF(Inputs!$B$28=1,MIN(1-F8,Inputs!$B$29*(Inputs!$B$25+Inputs!$B$30)/F5),1-F8) -> 0.9382528 | G9: =IF(Inputs!$B$28=1,MIN(1-G8,Inputs!$B$29*(Inputs!$B$25+Inputs!$B$30)/G5),1-G8) -> 0.845632
A11: Component | B11: Active state | C11: Active mA | D11: Sleep mA | E11: Duty: Standby | F11: Duty: Typical | G11: Duty: Finding | H11: Avg mA: Standby | I11: Avg mA: Typical | J11: Avg mA: Finding | K11: Peak mA | L11: Tier | M11: Basis
A12: MCU STM32U5A9 | B12: Run 160 MHz + DMA/GPU; sleep = Stop 2, full SRAM | C12: 8 | D12: 0.0175 | E12: 0.03 | F12: 0.1 | G12: 0.4 | H12: =$C12*E12+$D12*(1-E12) -> 0.256975 | I12: =$C12*F12+$D12*(1-F12) -> 0.81575 | J12: =$C12*G12+$D12*(1-G12) -> 3.2105 | K12: 15 | L12: MVP | M12: ST: 18.5 uA/MHz run (=3 mA core @160 MHz), 17.5 uA Stop 2 w/ 2.5 MB SRAM. 8 mA active adds GPU/OCTOSPI/DMA - estimate.
A13: GNSS MAX-M10S | B13: Continuous tracking; sleep = backup | C13: 8 | D13: 0.035 | E13: 1 | F13: 1 | G13: 1 | H13: =$C13*E13+$D13*(1-E13) -> 8 | I13: =$C13*F13+$D13*(1-F13) -> 8 | J13: =$C13*G13+$D13*(1-G13) -> 8 | K13: 25 | L13: MVP | M13: u-blox: <25 mW continuous tracking (~7.6 mA @3.3 V). Peak = acquisition. Backup current estimate.
A14: LoRa SX1262 TX | B14: +22 dBm | C14: 118 | D14: 0 | E14: =E8 -> 0.0205824 | F14: =F8 -> 0.0617472 | G14: =G8 -> 0.154368 | H14: =$C14*E14+$D14*(1-E14) -> 2.4287232 | I14: =$C14*F14+$D14*(1-F14) -> 7.2861696 | J14: =$C14*G14+$D14*(1-G14) -> 18.215424 | K14: 118 | L14: MVP | M14: Semtech: 118 mA @ +22 dBm. Duty from Inputs time-on-air / interval x relay.
A15: LoRa SX1262 RX | B15: LoRa RX 125 kHz; sleep = warm-start sleep | C15: 4.6 | D15: 0.0006 | E15: =E9 -> 0.9794176 | F15: =F9 -> 0.9382528 | G15: =G9 -> 0.845632 | H15: =$C15*E15+$D15*(1-E15) -> 4.5053333 | I15: =$C15*F15+$D15*(1-F15) -> 4.3159999 | J15: =$C15*G15+$D15*(1-G15) -> 3.8899998 | K15: 5 | L15: MVP | M15: Semtech: 4.6 mA RX (DC-DC). Sleep ~0.6 uA.
A16: UWB DWM3000 | B16: DS-TWR @10 Hz, RX-dominated; sleep = deep sleep | C16: 50 | D16: 0.0009 | E16: 0 | F16: 0 | G16: 0.03 | H16: =$C16*E16+$D16*(1-E16) -> 0.0009 | I16: =$C16*F16+$D16*(1-F16) -> 0.0009 | J16: =$C16*G16+$D16*(1-G16) -> 1.500873 | K16: 55 | L16: S2 | M16: DigiKey: RX 50-55 mA, TX 40-45 mA; sleep 0.26-0.85 uA. 3% = ~3 ms radio-on per 100 ms exchange - estimate.
A17: NFC PN7150 | B17: RF field polling (pairing only); sleep = standby/HPD | C17: 60 | D17: 0.01 | E17: 0.0005 | F17: 0.0005 | G17: 0.0005 | H17: =$C17*E17+$D17*(1-E17) -> 0.039995 | I17: =$C17*F17+$D17*(1-F17) -> 0.039995 | J17: =$C17*G17+$D17*(1-G17) -> 0.039995 | K17: 180 | L17: MVP | M17: NXP: 180 mA max RF driver current. Active avg + standby are estimates; keep in HPD via VEN except during pairing.
A18: IMU BNO085 (9-DOF fusion) | B18: Rotation vector (accel+gyro+mag fusion); sleep = accel-only significant-motion/tap wake | C18: 5.3 | D18: 0.1 | E18: 0.05 | F18: 0.15 | G18: 1 | H18: =$C18*E18+$D18*(1-E18) -> 0.36 | I18: =$C18*F18+$D18*(1-F18) -> 0.88 | J18: =$C18*G18+$D18*(1-G18) -> 5.3 | K18: 10 | L18: MVP | M18: CEVA BNO08X DS v1.16 sensor-metadata example: rotation vector 5.30 mA operating. Sleep 0.1 mA and 10 mA peak are estimates - DS power figures (sec 6.10) not extracted; measure with PPK2.
A19: AMOLED 1.43" 466x466 | B19: Dark UI (~30-40% APL); sleep = sleep-in | C19: 20 | D19: 0.05 | E19: 0.05 | F19: 0.15 | G19: 1 | H19: =$C19*E19+$D19*(1-E19) -> 1.0475 | I19: =$C19*F19+$D19*(1-F19) -> 3.0425 | J19: =$C19*G19+$D19*(1-G19) -> 20 | K19: 42 | L19: S1 | M19: Panel spec: ELVDD/ELVSS 33 mA + VCI 6 + VDDIO 3 mA typ (full pattern) = 42 peak. 20 mA dark-UI figure is an estimate - measure.
A20: Haptic DRV2605L + LRA | B20: LRA drive; sleep = EN low | C20: 65 | D20: 0.004 | E20: 0.001 | F20: 0.002 | G20: 0.005 | H20: =$C20*E20+$D20*(1-E20) -> 0.068996 | I20: =$C20*F20+$D20*(1-F20) -> 0.133992 | J20: =$C20*G20+$D20*(1-G20) -> 0.32898 | K20: 80 | L20: S1 | M20: LRA 0832: 58-80 mA rated. Driver standby estimate.
A21: Fuel gauge MAX17048 | B21: Active; sleep = hibernate | C21: 0.023 | D21: 0.003 | E21: 1 | F21: 1 | G21: 1 | H21: =$C21*E21+$D21*(1-E21) -> 0.023 | I21: =$C21*F21+$D21*(1-F21) -> 0.023 | J21: =$C21*G21+$D21*(1-G21) -> 0.023 | K21: 0.04 | L21: S1 | M21: ADI: 23 uA active, 3 uA hibernate (sits on battery; small modeling error).
A22: Regulator / charger Iq | B22: TPS63802 + LDO + BQ25180 | C22: 0.015 | D22: 0 | E22: 1 | F22: 1 | G22: 1 | H22: =$C22*E22+$D22*(1-E22) -> 0.015 | I22: =$C22*F22+$D22*(1-F22) -> 0.015 | J22: =$C22*G22+$D22*(1-G22) -> 0.015 | K22: 0 | L22: MVP | M22: Estimate - check TPS63802 Iq in the mode you configure.
A23: Encoder pull-ups + leakage | B23: - | C23: 0.02 | D23: 0 | E23: 1 | F23: 1 | G23: 1 | H23: =$C23*E23+$D23*(1-E23) -> 0.02 | I23: =$C23*F23+$D23*(1-F23) -> 0.02 | J23: =$C23*G23+$D23*(1-G23) -> 0.02 | K23: 0 | L23: S1 | M23: Estimate.
A25: Total rail current (mA @3.3 V) | H25: =SUM(H12:H23) -> 16.766423 | I25: =SUM(I12:I23) -> 24.573307 | J25: =SUM(J12:J23) -> 60.543772
A26: Battery current (mA) | H26: =H25*Inputs!$B$8/(Inputs!$B$7*Inputs!$B$9) -> 16.615374 | I26: =I25*Inputs!$B$8/(Inputs!$B$7*Inputs!$B$9) -> 24.351925 | J26: =J25*Inputs!$B$8/(Inputs!$B$7*Inputs!$B$9) -> 59.998332
A27: Runtime (h) | H27: =Inputs!$B$5*Inputs!$B$6/H26 -> 25.578721 | I27: =Inputs!$B$5*Inputs!$B$6/I26 -> 17.452419 | J27: =Inputs!$B$5*Inputs!$B$6/J26 -> 7.0835302
A28: Meets R-03? | H28: =IF(H27>=Inputs!$B$10,"YES","NO") -> YES | I28: =IF(I27>=Inputs!$B$10,"YES","NO") -> YES | J28: =IF(J27>=Inputs!$B$10,"YES","NO") -> NO
A30: Blended 8 h event day — avg battery current (mA) | H30: =SUMPRODUCT(H26:J26,E7:G7) -> 25.982428
A31: Blended runtime (h) | H31: =Inputs!$B$5*Inputs!$B$6/H30 -> 16.357209
A32: Blended margin vs R-03 (h) | H32: =H31-Inputs!$B$10 -> 8.3572087
A34: Peak current check
A35: Worst-case simultaneous peak, rail (mA) | K35: =SUM(K12:K23) -> 530.04
A36: Managed peak: firmware interlock, no NFC field during LoRa TX / UWB (mA) | K36: =K35-K17 -> 350.04
A37: Managed peak at battery, Vbat min (mA) | K37: =K36*Inputs!$B$8/(Inputs!$B$11*Inputs!$B$12) -> 452.99294
A38: Managed peak C-rate | K38: =K37/Inputs!$B$5 -> 0.90598588
A39: Within cell pulse rating? | K39: =IF(K38<=Inputs!$B$13,"YES","NO - add bulk cap / stagger loads") -> YES
A40: BQ25120A 300 mA buck sufficient? | K40: =IF(K36<=300,"YES","NO - use TPS63802-class buck-boost") -> NO - use TPS63802-class buck-boost

Sheet Sources
A1: Sources (checked Oct 2026)
A3: Item | B3: URL
A4: STM32U599/U5A9 power figures | B4: https://www.st.com/en/microcontrollers-microprocessors/stm32u599nj.html
A5: STM32U5A9VJT6Q price ($9.96 @10k) | B5: https://estore.st.com/en/products/microcontrollers-microprocessors/stm32-32-bit-arm-cortex-mcus/stm32-ultra-low-power-mcus/stm32u5-series/stm32u599-5a9/stm32u5a9vj.html
A6: STM32U5G9J-DK1 (active) / U5A9J-DK (NRND) | B6: https://st.com/en/evaluation-tools/stm32u5g9j-dk1.html
A7: STM32U5G9J-DK1 price | B7: https://fr.farnell.com/stmicroelectronics/stm32u5g9j-dk1/kit-discovery-32bit-arm-cortex/dp/4308671
A8: MAX-M10S datasheet | B8: https://content.u-blox.com/sites/default/files/MAX-M10S_DataSheet_UBX-20035208.pdf
A9: SparkFun MAX-M10S breakout | B9: https://sparkfun.com/products/18037
A10: SX1262 product page | B10: https://www.semtech.com/products/wireless-rf/lora-connect/sx1262
A11: SX1262 TX/RX currents | B11: https://everythingrf.com/products/rf-transceivers/semtech/531-690-sx1262
A12: DWM3000TR13 (DigiKey) | B12: https://www.digikey.fr/en/products/detail/qorvo/DWM3000TR13/24367320
A13: DWM3000 sleep current | B13: https://www.everythingrf.com/products/rf-modules/qorvo/528-483-dwm3000
A14: PN7150 price | B14: https://fr.farnell.com/nxp/pn7150b0hn-c11002y/rfid-lect-ecrit-13-56mhz-hvqfn/dp/2663167
... A25: Adafruit 1578 LiPo 500 mAh | B25: https://www.adafruit.com/product/1578
